<mujoco model="husky_ur5e_3finger">
  <compiler angle="radian"  autolimits="true"/>

  <default>
    <joint axis="0 1 0" armature="0.05" damping="0.05" />
    <position ctrlrange="-6.2831 6.2831" />
    <equality solref="0.0002 1" solimp="0.99 0.99 0.0001" />

    <default class="visual">
      <geom type="mesh" contype="0" conaffinity="0" group="2" />
    </default>
    <default class="collision">
      <geom type="capsule" group="3" />
      <default class="eef_collision">
        <geom type="cylinder" />
      </default>
    </default>
    <site size="0.001" rgba="0.5 0.5 0.5 0.3" group="4" />

    <default class="size3">
      <joint armature="0.1" damping="200" />
      <position kp="3500" forcerange="-500 500" />
      <default class="size3_limited">
        <joint range="-3.1415 3.1415" />
        <position ctrlrange="-3.1415 3.1415" />
      </default>
    </default>
    <default class="size1">
      <joint armature="0.1" damping="15" />
      <position kp="3000" forcerange="-28 28" />
    </default>

    <default class="gripper">
      <joint armature="0.01" damping="0.05"/>
      <geom type="mesh" contype="1" conaffinity="1" friction="1.0 0.005 0.001" group="2"/>
      <general gaintype="fixed" biastype="affine" gainprm="50" biasprm="0 -50 -5" forcerange="-10 10"/>
    </default>
  </default>

  <asset>
    <mesh name="base_link" file="../../robots/husky/meshes/base_link.stl" />
    <mesh name="wheel" file="../../robots/husky/meshes/wheel.stl" />
    <mesh name="top_plate" file="../../robots/husky/meshes/top_plate.stl" />
    <mesh name="user_rail" file="../../robots/husky/meshes/user_rail.stl" />
    <mesh name="bumper" file="../../robots/husky/meshes/bumper.stl" />

    <material name="black" specular="0.5" shininess="0.25" rgba="0.033 0.033 0.033 1" />
    <material name="jointgray" specular="0.5" shininess="0.25" rgba="0.278 0.278 0.278 1" />
    <material name="linkgray" specular="0.5" shininess="0.25" rgba="0.82 0.82 0.82 1" />
    <material name="urblue" specular="0.5" shininess="0.25" rgba="0.49 0.678 0.8 1" />

    <mesh file="../../robots/husky/meshes/base_0.obj" />
    <mesh file="../../robots/husky/meshes/base_1.obj" />
    <mesh file="../../robots/ur5e/meshes/shoulder_0.obj" />
    <mesh file="../../robots/ur5e/meshes/shoulder_1.obj" />
    <mesh file="../../robots/ur5e/meshes/shoulder_2.obj" />
    <mesh file="../../robots/ur5e/meshes/upperarm_0.obj" />
    <mesh file="../../robots/ur5e/meshes/upperarm_1.obj" />
    <mesh file="../../robots/ur5e/meshes/upperarm_2.obj" />
    <mesh file="../../robots/ur5e/meshes/upperarm_3.obj" />
    <mesh file="../../robots/ur5e/meshes/forearm_0.obj" />
    <mesh file="../../robots/ur5e/meshes/forearm_1.obj" />
    <mesh file="../../robots/ur5e/meshes/forearm_2.obj" />
    <mesh file="../../robots/ur5e/meshes/forearm_3.obj" />
    <mesh file="../../robots/ur5e/meshes/wrist1_0.obj" />
    <mesh file="../../robots/ur5e/meshes/wrist1_1.obj" />
    <mesh file="../../robots/ur5e/meshes/wrist1_2.obj" />
    <mesh file="../../robots/ur5e/meshes/wrist2_0.obj" />
    <mesh file="../../robots/ur5e/meshes/wrist2_1.obj" />
    <mesh file="../../robots/ur5e/meshes/wrist2_2.obj" />
    <mesh file="../../robots/ur5e/meshes/wrist3.obj" />

    <mesh name="palm"                  file="../../robots/grippers/meshes/palm.stl"                  scale="0.001 0.001 0.001"/>
    <mesh name="mid_finger_palm_joint" file="../../robots/grippers/meshes/mid_finger_palm_joint.stl" scale="0.001 0.001 0.001"/>
    <mesh name="two_finger_palm_joint" file="../../robots/grippers/meshes/two_finger_palm_joint.stl" scale="0.001 0.001 0.001"/>
    <mesh name="two_finger"            file="../../robots/grippers/meshes/two_finger.stl"            scale="0.001 0.001 0.001"/>
    <mesh name="two_finger_tip"        file="../../robots/grippers/meshes/two_finger_tip.stl"        scale="0.001 0.001 0.001"/>

    <material name="gripper_dark"     rgba="0.15 0.15 0.15 1" specular="0.3" shininess="0.5"/>
    <material name="gripper_metal"    rgba="0.6 0.6 0.65 1"   specular="0.7" shininess="0.8"/>
    <material name="fingertip_rubber" rgba="0.2 0.2 0.2 1"    specular="0.1" shininess="0.1"/>
  </asset>

  <worldbody>
    <body name="base_husky" pos="0 0 0.01" quat="1 0 0 0" >
      <inertial pos="0 0 0" quat="0.5 0.5 -0.5 0.5" mass="2.637" diaginertia="0.04411 0.02467 0.02467"/>
      <joint type="free" name="base_husky_joint" />
      <geom pos="0 0 0.14493" type="mesh" contype="0" conaffinity="0" group="1" density="0" rgba="0.1 0.1 0.1 1" mesh="base_link"/>
      <geom pos="0 0 0.14493" type="mesh" contype="0" conaffinity="0" group="1" density="0" rgba="0.8 0.8 0 1" mesh="top_plate"/>
      <geom pos="0.272 0 0.38993" type="mesh" contype="0" conaffinity="0" group="1" density="0" rgba="0.3 0.3 0.3 1" mesh="user_rail"/>
      <geom pos="0.48 0 0.23593" type="mesh" contype="0" conaffinity="0" group="1" density="0" rgba="0.3 0.3 0.3 1" mesh="bumper"/>
      <geom pos="-0.48 0 0.23593" quat="1.32679e-06 0 0 1" type="mesh" contype="0" conaffinity="0" group="1" density="0" rgba="0.3 0.3 0.3 1" mesh="bumper"/>
      <body name="front_left_wheel_link" pos="0.256 0.2854 0.17775" gravcomp="0">
        <inertial pos="0 0 0" quat="0.5 0.5 -0.5 0.5" mass="2.637" diaginertia="0.04411 0.02467 0.02467"/>
        <joint name="front_left_wheel" pos="0 0 0" axis="0 1 0"/>
        <geom type="mesh" contype="0" conaffinity="1" group="1" density="0" rgba="0.3 0.3 0.3 1" mesh="wheel"/>
      </body>
      <body name="front_right_wheel_link" pos="0.256 -0.2854 0.17775" gravcomp="0">
        <inertial pos="0 0 0" quat="0.5 0.5 -0.5 0.5" mass="2.637" diaginertia="0.04411 0.02467 0.02467"/>
        <joint name="front_right_wheel" pos="0 0 0" axis="0 1 0"/>
        <geom type="mesh" contype="0" conaffinity="1" group="1" density="0" rgba="0.3 0.3 0.3 1" mesh="wheel"/>
      </body>
      <body name="rear_left_wheel_link" pos="-0.256 0.2854 0.17775" gravcomp="0">
        <inertial pos="0 0 0" quat="0.5 0.5 -0.5 0.5" mass="2.637" diaginertia="0.04411 0.02467 0.02467"/>
        <joint name="rear_left_wheel" pos="0 0 0" axis="0 1 0"/>
        <geom type="mesh" contype="0" conaffinity="1" group="1" density="0" rgba="0.3 0.3 0.3 1" mesh="wheel"/>
      </body>
      <body name="rear_right_wheel_link" pos="-0.256 -0.2854 0.17775" gravcomp="0">
        <inertial pos="0 0 0" quat="0.5 0.5 -0.5 0.5" mass="2.637" diaginertia="0.04411 0.02467 0.02467"/>
        <joint name="rear_right_wheel" pos="0 0 0" axis="0 1 0"/>
        <geom type="mesh" contype="0" conaffinity="1" group="1" density="0" rgba="0.3 0.3 0.3 1" mesh="wheel"/>
      </body>

      <body name="base_ur5e" pos="-0.17 0 0.38993" quat="1 0 0 0">
        <inertial mass="4.0" pos="0 0 0" diaginertia="0.00443333156 0.00443333156 0.0072" />
        <geom mesh="base_0" material="black" class="visual" />
        <geom mesh="base_1" material="jointgray" class="visual" />
        <body name="shoulder_link" pos="0 0 0.163">
          <inertial mass="3.7" pos="0 0 0" diaginertia="0.0102675 0.0102675 0.00666" />
          <joint name="shoulder_pan_joint" class="size3" axis="0 0 1" />
          <geom mesh="shoulder_0" material="urblue" class="visual" />
          <geom mesh="shoulder_1" material="black" class="visual" />
          <geom mesh="shoulder_2" material="jointgray" class="visual" />
          <geom class="collision" size="0.06 0.06" pos="0 0 -0.04" />
          <body name="upper_arm_link" pos="0 0.138 0" quat="1 0 1 0">
            <inertial mass="8.393" pos="0 0 0.2125" diaginertia="0.133886 0.133886 0.0151074" />
            <joint name="shoulder_lift_joint" class="size3" />
            <geom mesh="upperarm_0" material="linkgray" class="visual" />
            <geom mesh="upperarm_1" material="black" class="visual" />
            <geom mesh="upperarm_2" material="jointgray" class="visual" />
            <geom mesh="upperarm_3" material="urblue" class="visual" />
            <geom class="collision" pos="0 -0.04 0" quat="1 1 0 0" size="0.06 0.06" />
            <geom class="collision" size="0.05 0.2" pos="0 0 0.2" />
            <body name="forearm_link" pos="0 -0.131 0.425">
              <inertial mass="2.275" pos="0 0 0.196" diaginertia="0.0311796 0.0311796 0.004095" />
              <joint name="elbow_joint" class="size3_limited" />
              <geom mesh="forearm_0" material="urblue" class="visual" />
              <geom mesh="forearm_1" material="linkgray" class="visual" />
              <geom mesh="forearm_2" material="black" class="visual" />
              <geom mesh="forearm_3" material="jointgray" class="visual" />
              <geom class="collision" pos="0 0.08 0" quat="1 1 0 0" size="0.055 0.06" />
              <geom class="collision" size="0.038 0.19" pos="0 0 0.2" />
              <body name="wrist_1_link" pos="0 0 0.392" quat="1 0 1 0">
                <inertial mass="1.219" pos="0 0.127 0" diaginertia="0.0025599 0.0025599 0.0021942" />
                <joint name="wrist_1_joint" class="size1" />
                <geom mesh="wrist1_0" material="black" class="visual" />
                <geom mesh="wrist1_1" material="urblue" class="visual" />
                <geom mesh="wrist1_2" material="jointgray" class="visual" />
                <geom class="collision" pos="0 0.05 0" quat="1 1 0 0" size="0.04 0.07" />
                <body name="wrist_2_link" pos="0 0.127 0">
                  <inertial mass="1.219" pos="0 0 0.1" diaginertia="0.0025599 0.0025599 0.0021942" />
                  <joint name="wrist_2_joint" axis="0 0 1" class="size1" />
                  <geom mesh="wrist2_0" material="black" class="visual" />
                  <geom mesh="wrist2_1" material="urblue" class="visual" />
                  <geom mesh="wrist2_2" material="jointgray" class="visual" />
                  <geom class="collision" size="0.04 0.06" pos="0 0 0.04" />
                  <geom class="collision" pos="0 0.02 0.1" quat="1 1 0 0" size="0.04 0.04" />
                  <body name="wrist_3_link" pos="0 0 0.1">
                    <inertial mass="0.1889" pos="0 0.0771683 0" quat="1 0 0 1"
                      diaginertia="0.000132134 9.90863e-05 9.90863e-05" />
                    <joint name="wrist_3_joint" class="size1" />
                    <geom material="linkgray" mesh="wrist3" class="visual" />
                    <geom class="eef_collision" pos="0 0.08 0" quat="1 1 0 0" size="0.04 0.02" />
                    <site name="attachment_site" pos="0 0.1 0" quat="-1 1 0 0" />
                    <site name="grasp_site" pos="0.15 0 0" size="0.005" rgba="1 1 0 0.9"/>

                    <!-- ============ 3-FINGER GRIPPER ============ -->
                    <body name="gripper_palm" pos="0 0.14 0" euler="-1.5708 3.14159 0" childclass="gripper">
                      <inertial mass="0.2" pos="0 0 0.02" diaginertia="0.0001 0.0001 0.0001"/>
                      <geom mesh="palm" material="gripper_dark"/>

                      <body name="center_palm" pos="0.0255 0 0">
                        <inertial mass="0.05" pos="0 0 0" diaginertia="0.00001 0.00001 0.00001"/>
                        <joint name="center_palm_joint" axis="0 0 1" range="-1.5708 1.5708"/>
                        <geom mesh="mid_finger_palm_joint" material="gripper_dark"/>
                        <body name="center_upper_finger" pos="0.036 0 -0.00825">
                          <inertial mass="0.05" pos="0 0 0" diaginertia="0.00001 0.00001 0.00001"/>
                          <joint name="center_upper_finger_joint" axis="0 1 0" range="-1.5708 1.5708"/>
                          <geom mesh="two_finger" material="gripper_metal"/>
                          <body name="center_lower_finger" pos="0 0 -0.0455">
                            <inertial mass="0.05" pos="0 0 0" diaginertia="0.00001 0.00001 0.00001"/>
                            <joint name="center_lower_finger_joint" axis="0 1 0" range="-1.5708 1.5708"/>
                            <geom mesh="two_finger" material="gripper_metal"/>
                            <body name="center_fingertip" pos="0 0 -0.0455">
                              <inertial mass="0.02" pos="0 0 0" diaginertia="0.000001 0.000001 0.000001"/>
                              <joint name="center_fingertip_joint" axis="0 1 0" range="-1.5708 1.5708"/>
                              <geom name="center_fingertip_geom" mesh="two_finger_tip" material="fingertip_rubber"/>
                              <site name="center_touch" pos="0 0 -0.02" size="0.008" rgba="1 0 0 0.3"/>
                            </body>
                          </body>
                        </body>
                      </body>

                      <body name="left_palm" pos="-0.0175 0.0245 0">
                        <inertial mass="0.05" pos="0 0 0" diaginertia="0.00001 0.00001 0.00001"/>
                        <joint name="left_palm_joint" axis="0 0 1" range="-1.5708 1.5708"/>
                        <geom mesh="two_finger_palm_joint" material="gripper_dark"/>
                        <body name="left_upper_finger" pos="-0.036 0 -0.00825" quat="0 0 0 1">
                          <inertial mass="0.05" pos="0 0 0" diaginertia="0.00001 0.00001 0.00001"/>
                          <joint name="left_upper_finger_joint" axis="0 1 0" range="-1.5708 1.5708"/>
                          <geom mesh="two_finger" material="gripper_metal"/>
                          <body name="left_lower_finger" pos="0 0 -0.0455">
                            <inertial mass="0.05" pos="0 0 0" diaginertia="0.00001 0.00001 0.00001"/>
                            <joint name="left_lower_finger_joint" axis="0 1 0" range="-1.5708 1.5708"/>
                            <geom mesh="two_finger" material="gripper_metal"/>
                            <body name="left_fingertip" pos="0 0 -0.0455">
                              <inertial mass="0.02" pos="0 0 0" diaginertia="0.000001 0.000001 0.000001"/>
                              <joint name="left_fingertip_joint" axis="0 1 0" range="-1.5708 1.5708"/>
                              <geom name="left_fingertip_geom" mesh="two_finger_tip" material="fingertip_rubber"/>
                              <site name="left_touch" pos="0 0 -0.02" size="0.008" rgba="1 0 0 0.3"/>
                            </body>
                          </body>
                        </body>
                      </body>

                      <body name="right_palm" pos="-0.0175 -0.0245 0">
                        <inertial mass="0.05" pos="0 0 0" diaginertia="0.00001 0.00001 0.00001"/>
                        <joint name="right_palm_joint" axis="0 0 1" range="-1.5708 1.5708"/>
                        <geom mesh="two_finger_palm_joint" material="gripper_dark"/>
                        <body name="right_upper_finger" pos="-0.036 0 -0.00825" quat="0 0 0 1">
                          <inertial mass="0.05" pos="0 0 0" diaginertia="0.00001 0.00001 0.00001"/>
                          <joint name="right_upper_finger_joint" axis="0 1 0" range="-1.5708 1.5708"/>
                          <geom mesh="two_finger" material="gripper_metal"/>
                          <body name="right_lower_finger" pos="0 0 -0.0455">
                            <inertial mass="0.05" pos="0 0 0" diaginertia="0.00001 0.00001 0.00001"/>
                            <joint name="right_lower_finger_joint" axis="0 1 0" range="-1.5708 1.5708"/>
                            <geom mesh="two_finger" material="gripper_metal"/>
                            <body name="right_fingertip" pos="0 0 -0.0455">
                              <inertial mass="0.02" pos="0 0 0" diaginertia="0.000001 0.000001 0.000001"/>
                              <joint name="right_fingertip_joint" axis="0 1 0" range="-1.5708 1.5708"/>
                              <geom name="right_fingertip_geom" mesh="two_finger_tip" material="fingertip_rubber"/>
                              <site name="right_touch" pos="0 0 -0.02" size="0.008" rgba="1 0 0 0.3"/>
                            </body>
                          </body>
                        </body>
                      </body>
                    </body>
                    <!-- ============ END 3-FINGER GRIPPER ============ -->

                  </body>
                </body>
              </body>
            </body>
          </body>
        </body>
      </body>
    </body>
  </worldbody>

  <contact>
    <exclude body1="base_husky" body2="base_ur5e"/>
  </contact>

  <actuator>
    <velocity name="front_left_actuator" ctrllimited="true" ctrlrange="-100.0 100.0" gear="1"
      kv="10" joint="front_left_wheel" />
    <velocity name="front_right_actuator" ctrllimited="true" ctrlrange="-100.0 100.0" gear="1"
      kv="10" joint="front_right_wheel" />
    <velocity name="rear_left_actuator" ctrllimited="true" ctrlrange="-100.0 100.0" gear="1"
      kv="10" joint="rear_left_wheel" />
    <velocity name="rear_right_actuator" ctrllimited="true" ctrlrange="-100.0 100.0" gear="1"
      kv="10" joint="rear_right_wheel" />

    <position class="size3" name="shoulder_pan" joint="shoulder_pan_joint" />
    <position class="size3" name="shoulder_lift" joint="shoulder_lift_joint" />
    <position class="size3_limited" name="elbow" joint="elbow_joint" />
    <position class="size1" name="wrist_1" joint="wrist_1_joint" />
    <position class="size1" name="wrist_2" joint="wrist_2_joint" />
    <position class="size1" name="wrist_3" joint="wrist_3_joint" />

    <general class="gripper" name="center_palm_act"         joint="center_palm_joint"         ctrlrange="-1.5708 1.5708"/>
    <general class="gripper" name="center_upper_finger_act" joint="center_upper_finger_joint" ctrlrange="-1.5708 1.5708"/>
    <general class="gripper" name="center_lower_finger_act" joint="center_lower_finger_joint" ctrlrange="-1.5708 1.5708"/>
    <general class="gripper" name="center_fingertip_act"    joint="center_fingertip_joint"    ctrlrange="-1.5708 1.5708"/>
    <general class="gripper" name="left_palm_act"           joint="left_palm_joint"           ctrlrange="-1.5708 1.5708"/>
    <general class="gripper" name="left_upper_finger_act"   joint="left_upper_finger_joint"   ctrlrange="-1.5708 1.5708"/>
    <general class="gripper" name="left_lower_finger_act"   joint="left_lower_finger_joint"   ctrlrange="-1.5708 1.5708"/>
    <general class="gripper" name="left_fingertip_act"      joint="left_fingertip_joint"      ctrlrange="-1.5708 1.5708"/>
    <general class="gripper" name="right_palm_act"          joint="right_palm_joint"          ctrlrange="-1.5708 1.5708"/>
    <general class="gripper" name="right_upper_finger_act"  joint="right_upper_finger_joint"  ctrlrange="-1.5708 1.5708"/>
    <general class="gripper" name="right_lower_finger_act"  joint="right_lower_finger_joint"  ctrlrange="-1.5708 1.5708"/>
    <general class="gripper" name="right_fingertip_act"     joint="right_fingertip_joint"     ctrlrange="-1.5708 1.5708"/>
  </actuator>

  <sensor>
    <touch name="center_touch_sensor" site="center_touch"/>
    <touch name="left_touch_sensor"   site="left_touch"/>
    <touch name="right_touch_sensor"  site="right_touch"/>

    <force name="ee_force"  site="attachment_site"/>
    <torque name="ee_torque" site="attachment_site"/>

    <jointpos name="jp_shoulder_pan"  joint="shoulder_pan_joint"/>
    <jointpos name="jp_shoulder_lift" joint="shoulder_lift_joint"/>
    <jointpos name="jp_elbow"         joint="elbow_joint"/>
    <jointpos name="jp_wrist_1"       joint="wrist_1_joint"/>
    <jointpos name="jp_wrist_2"       joint="wrist_2_joint"/>
    <jointpos name="jp_wrist_3"       joint="wrist_3_joint"/>
    <jointvel name="jv_shoulder_pan"  joint="shoulder_pan_joint"/>
    <jointvel name="jv_shoulder_lift" joint="shoulder_lift_joint"/>
    <jointvel name="jv_elbow"         joint="elbow_joint"/>
    <jointvel name="jv_wrist_1"       joint="wrist_1_joint"/>
    <jointvel name="jv_wrist_2"       joint="wrist_2_joint"/>
    <jointvel name="jv_wrist_3"       joint="wrist_3_joint"/>
  </sensor>

</mujoco>
